INFO:werkzeug: * Running on http://127.0.0.1:5000/ (Press CTRL+C to quit)
INFO:werkzeug:127.0.0.1 - - [22/Jun/2021 03:27:43] "[37mGET /serial-7975 HTTP/1.1[0m" 200 -
INFO:werkzeug:127.0.0.1 - - [22/Jun/2021 05:23:40] "[37mGET /serial-26246 HTTP/1.1[0m" 200 -
INFO:werkzeug:127.0.0.1 - - [22/Jun/2021 05:43:24] "[37mGET /serial-7975 HTTP/1.1[0m" 200 -
INFO:werkzeug:127.0.0.1 - - [22/Jun/2021 05:43:30] "[37mGET /movie-56628 HTTP/1.1[0m" 200 -
INFO:werkzeug: * Running on http://127.0.0.1:5000/ (Press CTRL+C to quit)
INFO:werkzeug:127.0.0.1 - - [22/Jun/2021 23:08:49] "[33mGET / HTTP/1.1[0m" 404 -
ERROR:app:Exception on /favicon.ico [GET]
Traceback (most recent call last):
  File "C:\python\lib\site-packages\flask\app.py", line 2447, in wsgi_app
    response = self.full_dispatch_request()
  File "C:\python\lib\site-packages\flask\app.py", line 1952, in full_dispatch_request
    rv = self.handle_user_exception(e)
  File "C:\python\lib\site-packages\flask\app.py", line 1821, in handle_user_exception
    reraise(exc_type, exc_value, tb)
  File "C:\python\lib\site-packages\flask\_compat.py", line 39, in reraise
    raise value
  File "C:\python\lib\site-packages\flask\app.py", line 1950, in full_dispatch_request
    rv = self.dispatch_request()
  File "C:\python\lib\site-packages\flask\app.py", line 1936, in dispatch_request
    return self.view_functions[rule.endpoint](**req.view_args)
  File "C:\Users\Artem\OneDrive\all_python\freelance-animebot\web\app.py", line 23, in main
    link = result['results'][0]['link']
KeyError: 'results'
INFO:werkzeug:127.0.0.1 - - [22/Jun/2021 23:08:50] "[35m[1mGET /favicon.ico HTTP/1.1[0m" 500 -
INFO:werkzeug:127.0.0.1 - - [22/Jun/2021 23:09:41] "[37mGET /serial-17976 HTTP/1.1[0m" 200 -
INFO:werkzeug:127.0.0.1 - - [22/Jun/2021 23:09:41] "[36mGET /static/css/main.css HTTP/1.1[0m" 304 -
INFO:werkzeug:127.0.0.1 - - [22/Jun/2021 23:09:41] "[33mGET /assets/images/favicon.png HTTP/1.1[0m" 404 -
INFO:werkzeug: * Running on http://127.0.0.1:5000/ (Press CTRL+C to quit)
INFO:werkzeug:127.0.0.1 - - [22/Jun/2021 23:11:34] "[37mGET /serial-17976 HTTP/1.1[0m" 200 -
INFO:werkzeug:127.0.0.1 - - [22/Jun/2021 23:11:34] "[37mGET /static/css/main.css HTTP/1.1[0m" 200 -
INFO:werkzeug:127.0.0.1 - - [22/Jun/2021 23:11:35] "[33mGET /assets/images/favicon.png HTTP/1.1[0m" 404 -
INFO:werkzeug:127.0.0.1 - - [22/Jun/2021 23:11:35] "[37mGET /static/favicon.ico HTTP/1.1[0m" 200 -
INFO:werkzeug: * Running on http://127.0.0.1:5000/ (Press CTRL+C to quit)
INFO:werkzeug: * Running on http://127.0.0.1:5000/ (Press CTRL+C to quit)
ERROR:app:Exception on /serial-26925 [GET]
Traceback (most recent call last):
  File "C:\python\lib\site-packages\sqlalchemy\engine\base.py", line 1276, in _execute_context
    self.dialect.do_execute(
  File "C:\python\lib\site-packages\sqlalchemy\engine\default.py", line 608, in do_execute
    cursor.execute(statement, parameters)
psycopg2.errors.InvalidTextRepresentation: invalid input syntax for type integer: "serial-26925"
LINE 3: WHERE anime.id = 'serial-26925'
                         ^


The above exception was the direct cause of the following exception:

Traceback (most recent call last):
  File "C:\python\lib\site-packages\flask\app.py", line 2447, in wsgi_app
    response = self.full_dispatch_request()
  File "C:\python\lib\site-packages\flask\app.py", line 1952, in full_dispatch_request
    rv = self.handle_user_exception(e)
  File "C:\python\lib\site-packages\flask\app.py", line 1821, in handle_user_exception
    reraise(exc_type, exc_value, tb)
  File "C:\python\lib\site-packages\flask\_compat.py", line 39, in reraise
    raise value
  File "C:\python\lib\site-packages\flask\app.py", line 1950, in full_dispatch_request
    rv = self.dispatch_request()
  File "C:\python\lib\site-packages\flask\app.py", line 1936, in dispatch_request
    return self.view_functions[rule.endpoint](**req.view_args)
  File "C:\Users\Artem\OneDrive\all_python\freelance-animebot\web\app.py", line 16, in main
    anime = db_sess.query(Anime).get(id)
  File "C:\python\lib\site-packages\sqlalchemy\orm\query.py", line 1018, in get
    return self._get_impl(ident, loading.load_on_pk_identity)
  File "C:\python\lib\site-packages\sqlalchemy\orm\query.py", line 1135, in _get_impl
    return db_load_fn(self, primary_key_identity)
  File "C:\python\lib\site-packages\sqlalchemy\orm\loading.py", line 286, in load_on_pk_identity
    return q.one()
  File "C:\python\lib\site-packages\sqlalchemy\orm\query.py", line 3490, in one
    ret = self.one_or_none()
  File "C:\python\lib\site-packages\sqlalchemy\orm\query.py", line 3459, in one_or_none
    ret = list(self)
  File "C:\python\lib\site-packages\sqlalchemy\orm\query.py", line 3535, in __iter__
    return self._execute_and_instances(context)
  File "C:\python\lib\site-packages\sqlalchemy\orm\query.py", line 3560, in _execute_and_instances
    result = conn.execute(querycontext.statement, self._params)
  File "C:\python\lib\site-packages\sqlalchemy\engine\base.py", line 1011, in execute
    return meth(self, multiparams, params)
  File "C:\python\lib\site-packages\sqlalchemy\sql\elements.py", line 298, in _execute_on_connection
    return connection._execute_clauseelement(self, multiparams, params)
  File "C:\python\lib\site-packages\sqlalchemy\engine\base.py", line 1124, in _execute_clauseelement
    ret = self._execute_context(
  File "C:\python\lib\site-packages\sqlalchemy\engine\base.py", line 1316, in _execute_context
    self._handle_dbapi_exception(
  File "C:\python\lib\site-packages\sqlalchemy\engine\base.py", line 1510, in _handle_dbapi_exception
    util.raise_(
  File "C:\python\lib\site-packages\sqlalchemy\util\compat.py", line 182, in raise_
    raise exception
  File "C:\python\lib\site-packages\sqlalchemy\engine\base.py", line 1276, in _execute_context
    self.dialect.do_execute(
  File "C:\python\lib\site-packages\sqlalchemy\engine\default.py", line 608, in do_execute
    cursor.execute(statement, parameters)
sqlalchemy.exc.DataError: (psycopg2.errors.InvalidTextRepresentation) invalid input syntax for type integer: "serial-26925"
LINE 3: WHERE anime.id = 'serial-26925'
                         ^

[SQL: SELECT anime.id AS anime_id, anime.kodik_id AS anime_kodik_id, anime.title AS anime_title, anime.iframe_link AS anime_iframe_link, anime.views AS anime_views, anime.status AS anime_status 
FROM anime 
WHERE anime.id = %(param_1)s]
[parameters: {'param_1': 'serial-26925'}]
(Background on this error at: http://sqlalche.me/e/13/9h9h)
INFO:werkzeug:127.0.0.1 - - [23/Jun/2021 03:14:42] "[35m[1mGET /serial-26925 HTTP/1.1[0m" 500 -
ERROR:app:Exception on /favicon.ico [GET]
Traceback (most recent call last):
  File "C:\python\lib\site-packages\sqlalchemy\engine\base.py", line 1276, in _execute_context
    self.dialect.do_execute(
  File "C:\python\lib\site-packages\sqlalchemy\engine\default.py", line 608, in do_execute
    cursor.execute(statement, parameters)
psycopg2.errors.InvalidTextRepresentation: invalid input syntax for type integer: "favicon.ico"
LINE 3: WHERE anime.id = 'favicon.ico'
                         ^


The above exception was the direct cause of the following exception:

Traceback (most recent call last):
  File "C:\python\lib\site-packages\flask\app.py", line 2447, in wsgi_app
    response = self.full_dispatch_request()
  File "C:\python\lib\site-packages\flask\app.py", line 1952, in full_dispatch_request
    rv = self.handle_user_exception(e)
  File "C:\python\lib\site-packages\flask\app.py", line 1821, in handle_user_exception
    reraise(exc_type, exc_value, tb)
  File "C:\python\lib\site-packages\flask\_compat.py", line 39, in reraise
    raise value
  File "C:\python\lib\site-packages\flask\app.py", line 1950, in full_dispatch_request
    rv = self.dispatch_request()
  File "C:\python\lib\site-packages\flask\app.py", line 1936, in dispatch_request
    return self.view_functions[rule.endpoint](**req.view_args)
  File "C:\Users\Artem\OneDrive\all_python\freelance-animebot\web\app.py", line 16, in main
    anime = db_sess.query(Anime).get(id)
  File "C:\python\lib\site-packages\sqlalchemy\orm\query.py", line 1018, in get
    return self._get_impl(ident, loading.load_on_pk_identity)
  File "C:\python\lib\site-packages\sqlalchemy\orm\query.py", line 1135, in _get_impl
    return db_load_fn(self, primary_key_identity)
  File "C:\python\lib\site-packages\sqlalchemy\orm\loading.py", line 286, in load_on_pk_identity
    return q.one()
  File "C:\python\lib\site-packages\sqlalchemy\orm\query.py", line 3490, in one
    ret = self.one_or_none()
  File "C:\python\lib\site-packages\sqlalchemy\orm\query.py", line 3459, in one_or_none
    ret = list(self)
  File "C:\python\lib\site-packages\sqlalchemy\orm\query.py", line 3535, in __iter__
    return self._execute_and_instances(context)
  File "C:\python\lib\site-packages\sqlalchemy\orm\query.py", line 3560, in _execute_and_instances
    result = conn.execute(querycontext.statement, self._params)
  File "C:\python\lib\site-packages\sqlalchemy\engine\base.py", line 1011, in execute
    return meth(self, multiparams, params)
  File "C:\python\lib\site-packages\sqlalchemy\sql\elements.py", line 298, in _execute_on_connection
    return connection._execute_clauseelement(self, multiparams, params)
  File "C:\python\lib\site-packages\sqlalchemy\engine\base.py", line 1124, in _execute_clauseelement
    ret = self._execute_context(
  File "C:\python\lib\site-packages\sqlalchemy\engine\base.py", line 1316, in _execute_context
    self._handle_dbapi_exception(
  File "C:\python\lib\site-packages\sqlalchemy\engine\base.py", line 1510, in _handle_dbapi_exception
    util.raise_(
  File "C:\python\lib\site-packages\sqlalchemy\util\compat.py", line 182, in raise_
    raise exception
  File "C:\python\lib\site-packages\sqlalchemy\engine\base.py", line 1276, in _execute_context
    self.dialect.do_execute(
  File "C:\python\lib\site-packages\sqlalchemy\engine\default.py", line 608, in do_execute
    cursor.execute(statement, parameters)
sqlalchemy.exc.DataError: (psycopg2.errors.InvalidTextRepresentation) invalid input syntax for type integer: "favicon.ico"
LINE 3: WHERE anime.id = 'favicon.ico'
                         ^

[SQL: SELECT anime.id AS anime_id, anime.kodik_id AS anime_kodik_id, anime.title AS anime_title, anime.iframe_link AS anime_iframe_link, anime.views AS anime_views, anime.status AS anime_status 
FROM anime 
WHERE anime.id = %(param_1)s]
[parameters: {'param_1': 'favicon.ico'}]
(Background on this error at: http://sqlalche.me/e/13/9h9h)
INFO:werkzeug:127.0.0.1 - - [23/Jun/2021 03:14:42] "[35m[1mGET /favicon.ico HTTP/1.1[0m" 500 -
INFO:werkzeug: * Running on http://127.0.0.1:5000/ (Press CTRL+C to quit)
INFO:werkzeug:127.0.0.1 - - [23/Jun/2021 03:17:07] "[33mGET /serial-26925 HTTP/1.1[0m" 404 -
INFO:werkzeug:127.0.0.1 - - [23/Jun/2021 03:17:08] "[33mGET /favicon.ico HTTP/1.1[0m" 404 -
INFO:werkzeug: * Running on http://127.0.0.1:5000/ (Press CTRL+C to quit)
ERROR:app:Exception on /id/serial-26925 [GET]
Traceback (most recent call last):
  File "C:\python\lib\site-packages\sqlalchemy\engine\base.py", line 1276, in _execute_context
    self.dialect.do_execute(
  File "C:\python\lib\site-packages\sqlalchemy\engine\default.py", line 608, in do_execute
    cursor.execute(statement, parameters)
psycopg2.errors.InvalidTextRepresentation: invalid input syntax for type integer: "serial-26925"
LINE 3: WHERE anime.id = 'serial-26925'
                         ^


The above exception was the direct cause of the following exception:

Traceback (most recent call last):
  File "C:\python\lib\site-packages\flask\app.py", line 2447, in wsgi_app
    response = self.full_dispatch_request()
  File "C:\python\lib\site-packages\flask\app.py", line 1952, in full_dispatch_request
    rv = self.handle_user_exception(e)
  File "C:\python\lib\site-packages\flask\app.py", line 1821, in handle_user_exception
    reraise(exc_type, exc_value, tb)
  File "C:\python\lib\site-packages\flask\_compat.py", line 39, in reraise
    raise value
  File "C:\python\lib\site-packages\flask\app.py", line 1950, in full_dispatch_request
    rv = self.dispatch_request()
  File "C:\python\lib\site-packages\flask\app.py", line 1936, in dispatch_request
    return self.view_functions[rule.endpoint](**req.view_args)
  File "C:\Users\Artem\OneDrive\all_python\freelance-animebot\web\app.py", line 16, in main
    anime = db_sess.query(Anime).get(id)
  File "C:\python\lib\site-packages\sqlalchemy\orm\query.py", line 1018, in get
    return self._get_impl(ident, loading.load_on_pk_identity)
  File "C:\python\lib\site-packages\sqlalchemy\orm\query.py", line 1135, in _get_impl
    return db_load_fn(self, primary_key_identity)
  File "C:\python\lib\site-packages\sqlalchemy\orm\loading.py", line 286, in load_on_pk_identity
    return q.one()
  File "C:\python\lib\site-packages\sqlalchemy\orm\query.py", line 3490, in one
    ret = self.one_or_none()
  File "C:\python\lib\site-packages\sqlalchemy\orm\query.py", line 3459, in one_or_none
    ret = list(self)
  File "C:\python\lib\site-packages\sqlalchemy\orm\query.py", line 3535, in __iter__
    return self._execute_and_instances(context)
  File "C:\python\lib\site-packages\sqlalchemy\orm\query.py", line 3560, in _execute_and_instances
    result = conn.execute(querycontext.statement, self._params)
  File "C:\python\lib\site-packages\sqlalchemy\engine\base.py", line 1011, in execute
    return meth(self, multiparams, params)
  File "C:\python\lib\site-packages\sqlalchemy\sql\elements.py", line 298, in _execute_on_connection
    return connection._execute_clauseelement(self, multiparams, params)
  File "C:\python\lib\site-packages\sqlalchemy\engine\base.py", line 1124, in _execute_clauseelement
    ret = self._execute_context(
  File "C:\python\lib\site-packages\sqlalchemy\engine\base.py", line 1316, in _execute_context
    self._handle_dbapi_exception(
  File "C:\python\lib\site-packages\sqlalchemy\engine\base.py", line 1510, in _handle_dbapi_exception
    util.raise_(
  File "C:\python\lib\site-packages\sqlalchemy\util\compat.py", line 182, in raise_
    raise exception
  File "C:\python\lib\site-packages\sqlalchemy\engine\base.py", line 1276, in _execute_context
    self.dialect.do_execute(
  File "C:\python\lib\site-packages\sqlalchemy\engine\default.py", line 608, in do_execute
    cursor.execute(statement, parameters)
sqlalchemy.exc.DataError: (psycopg2.errors.InvalidTextRepresentation) invalid input syntax for type integer: "serial-26925"
LINE 3: WHERE anime.id = 'serial-26925'
                         ^

[SQL: SELECT anime.id AS anime_id, anime.kodik_id AS anime_kodik_id, anime.title AS anime_title, anime.iframe_link AS anime_iframe_link, anime.views AS anime_views, anime.status AS anime_status 
FROM anime 
WHERE anime.id = %(param_1)s]
[parameters: {'param_1': 'serial-26925'}]
(Background on this error at: http://sqlalche.me/e/13/9h9h)
INFO:werkzeug:127.0.0.1 - - [23/Jun/2021 03:22:18] "[35m[1mGET /id/serial-26925 HTTP/1.1[0m" 500 -
INFO:werkzeug:127.0.0.1 - - [23/Jun/2021 03:22:18] "[33mGET /favicon.ico HTTP/1.1[0m" 404 -
ERROR:app:Exception on /id/serial-26925 [GET]
Traceback (most recent call last):
  File "C:\python\lib\site-packages\sqlalchemy\engine\base.py", line 1276, in _execute_context
    self.dialect.do_execute(
  File "C:\python\lib\site-packages\sqlalchemy\engine\default.py", line 608, in do_execute
    cursor.execute(statement, parameters)
psycopg2.errors.InvalidTextRepresentation: invalid input syntax for type integer: "serial-26925"
LINE 3: WHERE anime.id = 'serial-26925'
                         ^


The above exception was the direct cause of the following exception:

Traceback (most recent call last):
  File "C:\python\lib\site-packages\flask\app.py", line 2447, in wsgi_app
    response = self.full_dispatch_request()
  File "C:\python\lib\site-packages\flask\app.py", line 1952, in full_dispatch_request
    rv = self.handle_user_exception(e)
  File "C:\python\lib\site-packages\flask\app.py", line 1821, in handle_user_exception
    reraise(exc_type, exc_value, tb)
  File "C:\python\lib\site-packages\flask\_compat.py", line 39, in reraise
    raise value
  File "C:\python\lib\site-packages\flask\app.py", line 1950, in full_dispatch_request
    rv = self.dispatch_request()
  File "C:\python\lib\site-packages\flask\app.py", line 1936, in dispatch_request
    return self.view_functions[rule.endpoint](**req.view_args)
  File "C:\Users\Artem\OneDrive\all_python\freelance-animebot\web\app.py", line 16, in main
    anime = db_sess.query(Anime).get(id)
  File "C:\python\lib\site-packages\sqlalchemy\orm\query.py", line 1018, in get
    return self._get_impl(ident, loading.load_on_pk_identity)
  File "C:\python\lib\site-packages\sqlalchemy\orm\query.py", line 1135, in _get_impl
    return db_load_fn(self, primary_key_identity)
  File "C:\python\lib\site-packages\sqlalchemy\orm\loading.py", line 286, in load_on_pk_identity
    return q.one()
  File "C:\python\lib\site-packages\sqlalchemy\orm\query.py", line 3490, in one
    ret = self.one_or_none()
  File "C:\python\lib\site-packages\sqlalchemy\orm\query.py", line 3459, in one_or_none
    ret = list(self)
  File "C:\python\lib\site-packages\sqlalchemy\orm\query.py", line 3535, in __iter__
    return self._execute_and_instances(context)
  File "C:\python\lib\site-packages\sqlalchemy\orm\query.py", line 3560, in _execute_and_instances
    result = conn.execute(querycontext.statement, self._params)
  File "C:\python\lib\site-packages\sqlalchemy\engine\base.py", line 1011, in execute
    return meth(self, multiparams, params)
  File "C:\python\lib\site-packages\sqlalchemy\sql\elements.py", line 298, in _execute_on_connection
    return connection._execute_clauseelement(self, multiparams, params)
  File "C:\python\lib\site-packages\sqlalchemy\engine\base.py", line 1124, in _execute_clauseelement
    ret = self._execute_context(
  File "C:\python\lib\site-packages\sqlalchemy\engine\base.py", line 1316, in _execute_context
    self._handle_dbapi_exception(
  File "C:\python\lib\site-packages\sqlalchemy\engine\base.py", line 1510, in _handle_dbapi_exception
    util.raise_(
  File "C:\python\lib\site-packages\sqlalchemy\util\compat.py", line 182, in raise_
    raise exception
  File "C:\python\lib\site-packages\sqlalchemy\engine\base.py", line 1276, in _execute_context
    self.dialect.do_execute(
  File "C:\python\lib\site-packages\sqlalchemy\engine\default.py", line 608, in do_execute
    cursor.execute(statement, parameters)
sqlalchemy.exc.DataError: (psycopg2.errors.InvalidTextRepresentation) invalid input syntax for type integer: "serial-26925"
LINE 3: WHERE anime.id = 'serial-26925'
                         ^

[SQL: SELECT anime.id AS anime_id, anime.kodik_id AS anime_kodik_id, anime.title AS anime_title, anime.iframe_link AS anime_iframe_link, anime.views AS anime_views, anime.status AS anime_status 
FROM anime 
WHERE anime.id = %(param_1)s]
[parameters: {'param_1': 'serial-26925'}]
(Background on this error at: http://sqlalche.me/e/13/9h9h)
INFO:werkzeug:127.0.0.1 - - [23/Jun/2021 03:22:37] "[35m[1mGET /id/serial-26925 HTTP/1.1[0m" 500 -
INFO:werkzeug:127.0.0.1 - - [23/Jun/2021 03:22:37] "[33mGET /favicon.ico HTTP/1.1[0m" 404 -
ERROR:app:Exception on /id/serial-4277 [GET]
Traceback (most recent call last):
  File "C:\python\lib\site-packages\sqlalchemy\engine\base.py", line 1276, in _execute_context
    self.dialect.do_execute(
  File "C:\python\lib\site-packages\sqlalchemy\engine\default.py", line 608, in do_execute
    cursor.execute(statement, parameters)
psycopg2.errors.InvalidTextRepresentation: invalid input syntax for type integer: "serial-4277"
LINE 3: WHERE anime.id = 'serial-4277'
                         ^


The above exception was the direct cause of the following exception:

Traceback (most recent call last):
  File "C:\python\lib\site-packages\flask\app.py", line 2447, in wsgi_app
    response = self.full_dispatch_request()
  File "C:\python\lib\site-packages\flask\app.py", line 1952, in full_dispatch_request
    rv = self.handle_user_exception(e)
  File "C:\python\lib\site-packages\flask\app.py", line 1821, in handle_user_exception
    reraise(exc_type, exc_value, tb)
  File "C:\python\lib\site-packages\flask\_compat.py", line 39, in reraise
    raise value
  File "C:\python\lib\site-packages\flask\app.py", line 1950, in full_dispatch_request
    rv = self.dispatch_request()
  File "C:\python\lib\site-packages\flask\app.py", line 1936, in dispatch_request
    return self.view_functions[rule.endpoint](**req.view_args)
  File "C:\Users\Artem\OneDrive\all_python\freelance-animebot\web\app.py", line 16, in main
    anime = db_sess.query(Anime).get(id)
  File "C:\python\lib\site-packages\sqlalchemy\orm\query.py", line 1018, in get
    return self._get_impl(ident, loading.load_on_pk_identity)
  File "C:\python\lib\site-packages\sqlalchemy\orm\query.py", line 1135, in _get_impl
    return db_load_fn(self, primary_key_identity)
  File "C:\python\lib\site-packages\sqlalchemy\orm\loading.py", line 286, in load_on_pk_identity
    return q.one()
  File "C:\python\lib\site-packages\sqlalchemy\orm\query.py", line 3490, in one
    ret = self.one_or_none()
  File "C:\python\lib\site-packages\sqlalchemy\orm\query.py", line 3459, in one_or_none
    ret = list(self)
  File "C:\python\lib\site-packages\sqlalchemy\orm\query.py", line 3535, in __iter__
    return self._execute_and_instances(context)
  File "C:\python\lib\site-packages\sqlalchemy\orm\query.py", line 3560, in _execute_and_instances
    result = conn.execute(querycontext.statement, self._params)
  File "C:\python\lib\site-packages\sqlalchemy\engine\base.py", line 1011, in execute
    return meth(self, multiparams, params)
  File "C:\python\lib\site-packages\sqlalchemy\sql\elements.py", line 298, in _execute_on_connection
    return connection._execute_clauseelement(self, multiparams, params)
  File "C:\python\lib\site-packages\sqlalchemy\engine\base.py", line 1124, in _execute_clauseelement
    ret = self._execute_context(
  File "C:\python\lib\site-packages\sqlalchemy\engine\base.py", line 1316, in _execute_context
    self._handle_dbapi_exception(
  File "C:\python\lib\site-packages\sqlalchemy\engine\base.py", line 1510, in _handle_dbapi_exception
    util.raise_(
  File "C:\python\lib\site-packages\sqlalchemy\util\compat.py", line 182, in raise_
    raise exception
  File "C:\python\lib\site-packages\sqlalchemy\engine\base.py", line 1276, in _execute_context
    self.dialect.do_execute(
  File "C:\python\lib\site-packages\sqlalchemy\engine\default.py", line 608, in do_execute
    cursor.execute(statement, parameters)
sqlalchemy.exc.DataError: (psycopg2.errors.InvalidTextRepresentation) invalid input syntax for type integer: "serial-4277"
LINE 3: WHERE anime.id = 'serial-4277'
                         ^

[SQL: SELECT anime.id AS anime_id, anime.kodik_id AS anime_kodik_id, anime.title AS anime_title, anime.iframe_link AS anime_iframe_link, anime.views AS anime_views, anime.status AS anime_status 
FROM anime 
WHERE anime.id = %(param_1)s]
[parameters: {'param_1': 'serial-4277'}]
(Background on this error at: http://sqlalche.me/e/13/9h9h)
INFO:werkzeug:127.0.0.1 - - [23/Jun/2021 03:48:07] "[35m[1mGET /id/serial-4277 HTTP/1.1[0m" 500 -
INFO:werkzeug: * Running on http://127.0.0.1:5000/ (Press CTRL+C to quit)
ERROR:app:Exception on /id/serial-4277 [GET]
Traceback (most recent call last):
  File "C:\python\lib\site-packages\sqlalchemy\engine\base.py", line 1276, in _execute_context
    self.dialect.do_execute(
  File "C:\python\lib\site-packages\sqlalchemy\engine\default.py", line 608, in do_execute
    cursor.execute(statement, parameters)
psycopg2.errors.InvalidTextRepresentation: invalid input syntax for type integer: "serial-4277"
LINE 3: WHERE anime.id = 'serial-4277'
                         ^


The above exception was the direct cause of the following exception:

Traceback (most recent call last):
  File "C:\python\lib\site-packages\flask\app.py", line 2447, in wsgi_app
    response = self.full_dispatch_request()
  File "C:\python\lib\site-packages\flask\app.py", line 1952, in full_dispatch_request
    rv = self.handle_user_exception(e)
  File "C:\python\lib\site-packages\flask\app.py", line 1821, in handle_user_exception
    reraise(exc_type, exc_value, tb)
  File "C:\python\lib\site-packages\flask\_compat.py", line 39, in reraise
    raise value
  File "C:\python\lib\site-packages\flask\app.py", line 1950, in full_dispatch_request
    rv = self.dispatch_request()
  File "C:\python\lib\site-packages\flask\app.py", line 1936, in dispatch_request
    return self.view_functions[rule.endpoint](**req.view_args)
  File "C:\Users\Artem\OneDrive\all_python\freelance-animebot\web\app.py", line 16, in main
    anime = db_sess.query(Anime).get(id)
  File "C:\python\lib\site-packages\sqlalchemy\orm\query.py", line 1018, in get
    return self._get_impl(ident, loading.load_on_pk_identity)
  File "C:\python\lib\site-packages\sqlalchemy\orm\query.py", line 1135, in _get_impl
    return db_load_fn(self, primary_key_identity)
  File "C:\python\lib\site-packages\sqlalchemy\orm\loading.py", line 286, in load_on_pk_identity
    return q.one()
  File "C:\python\lib\site-packages\sqlalchemy\orm\query.py", line 3490, in one
    ret = self.one_or_none()
  File "C:\python\lib\site-packages\sqlalchemy\orm\query.py", line 3459, in one_or_none
    ret = list(self)
  File "C:\python\lib\site-packages\sqlalchemy\orm\query.py", line 3535, in __iter__
    return self._execute_and_instances(context)
  File "C:\python\lib\site-packages\sqlalchemy\orm\query.py", line 3560, in _execute_and_instances
    result = conn.execute(querycontext.statement, self._params)
  File "C:\python\lib\site-packages\sqlalchemy\engine\base.py", line 1011, in execute
    return meth(self, multiparams, params)
  File "C:\python\lib\site-packages\sqlalchemy\sql\elements.py", line 298, in _execute_on_connection
    return connection._execute_clauseelement(self, multiparams, params)
  File "C:\python\lib\site-packages\sqlalchemy\engine\base.py", line 1124, in _execute_clauseelement
    ret = self._execute_context(
  File "C:\python\lib\site-packages\sqlalchemy\engine\base.py", line 1316, in _execute_context
    self._handle_dbapi_exception(
  File "C:\python\lib\site-packages\sqlalchemy\engine\base.py", line 1510, in _handle_dbapi_exception
    util.raise_(
  File "C:\python\lib\site-packages\sqlalchemy\util\compat.py", line 182, in raise_
    raise exception
  File "C:\python\lib\site-packages\sqlalchemy\engine\base.py", line 1276, in _execute_context
    self.dialect.do_execute(
  File "C:\python\lib\site-packages\sqlalchemy\engine\default.py", line 608, in do_execute
    cursor.execute(statement, parameters)
sqlalchemy.exc.DataError: (psycopg2.errors.InvalidTextRepresentation) invalid input syntax for type integer: "serial-4277"
LINE 3: WHERE anime.id = 'serial-4277'
                         ^

[SQL: SELECT anime.id AS anime_id, anime.kodik_id AS anime_kodik_id, anime.title AS anime_title, anime.iframe_link AS anime_iframe_link, anime.views AS anime_views, anime.status AS anime_status 
FROM anime 
WHERE anime.id = %(param_1)s]
[parameters: {'param_1': 'serial-4277'}]
(Background on this error at: http://sqlalche.me/e/13/9h9h)
INFO:werkzeug:127.0.0.1 - - [23/Jun/2021 04:10:20] "[35m[1mGET /id/serial-4277 HTTP/1.1[0m" 500 -
INFO:werkzeug: * Running on http://127.0.0.1:5000/ (Press CTRL+C to quit)
ERROR:app:Exception on /id/serial-4277 [GET]
Traceback (most recent call last):
  File "C:\python\lib\site-packages\flask\app.py", line 2447, in wsgi_app
    response = self.full_dispatch_request()
  File "C:\python\lib\site-packages\flask\app.py", line 1952, in full_dispatch_request
    rv = self.handle_user_exception(e)
  File "C:\python\lib\site-packages\flask\app.py", line 1821, in handle_user_exception
    reraise(exc_type, exc_value, tb)
  File "C:\python\lib\site-packages\flask\_compat.py", line 39, in reraise
    raise value
  File "C:\python\lib\site-packages\flask\app.py", line 1950, in full_dispatch_request
    rv = self.dispatch_request()
  File "C:\python\lib\site-packages\flask\app.py", line 1936, in dispatch_request
    return self.view_functions[rule.endpoint](**req.view_args)
  File "C:\Users\Artem\OneDrive\all_python\freelance-animebot\web\app.py", line 21, in main
    img_link = anime.poster_link
AttributeError: 'Anime' object has no attribute 'poster_link'
INFO:werkzeug:127.0.0.1 - - [23/Jun/2021 04:11:33] "[35m[1mGET /id/serial-4277 HTTP/1.1[0m" 500 -
ERROR:app:Exception on /id/serial-4277 [GET]
Traceback (most recent call last):
  File "C:\python\lib\site-packages\flask\app.py", line 2447, in wsgi_app
    response = self.full_dispatch_request()
  File "C:\python\lib\site-packages\flask\app.py", line 1952, in full_dispatch_request
    rv = self.handle_user_exception(e)
  File "C:\python\lib\site-packages\flask\app.py", line 1821, in handle_user_exception
    reraise(exc_type, exc_value, tb)
  File "C:\python\lib\site-packages\flask\_compat.py", line 39, in reraise
    raise value
  File "C:\python\lib\site-packages\flask\app.py", line 1950, in full_dispatch_request
    rv = self.dispatch_request()
  File "C:\python\lib\site-packages\flask\app.py", line 1936, in dispatch_request
    return self.view_functions[rule.endpoint](**req.view_args)
  File "C:\Users\Artem\OneDrive\all_python\freelance-animebot\web\app.py", line 21, in main
    img_link = anime.poster_link
AttributeError: 'Anime' object has no attribute 'poster_link'
INFO:werkzeug:127.0.0.1 - - [23/Jun/2021 04:11:35] "[35m[1mGET /id/serial-4277 HTTP/1.1[0m" 500 -
INFO:werkzeug:127.0.0.1 - - [23/Jun/2021 04:11:35] "[33mGET /favicon.ico HTTP/1.1[0m" 404 -
ERROR:app:Exception on /id/serial-4277 [GET]
Traceback (most recent call last):
  File "C:\python\lib\site-packages\flask\app.py", line 2447, in wsgi_app
    response = self.full_dispatch_request()
  File "C:\python\lib\site-packages\flask\app.py", line 1952, in full_dispatch_request
    rv = self.handle_user_exception(e)
  File "C:\python\lib\site-packages\flask\app.py", line 1821, in handle_user_exception
    reraise(exc_type, exc_value, tb)
  File "C:\python\lib\site-packages\flask\_compat.py", line 39, in reraise
    raise value
  File "C:\python\lib\site-packages\flask\app.py", line 1950, in full_dispatch_request
    rv = self.dispatch_request()
  File "C:\python\lib\site-packages\flask\app.py", line 1936, in dispatch_request
    return self.view_functions[rule.endpoint](**req.view_args)
  File "C:\Users\Artem\OneDrive\all_python\freelance-animebot\web\app.py", line 21, in main
    img_link = anime.poster_link
AttributeError: 'Anime' object has no attribute 'poster_link'
INFO:werkzeug:127.0.0.1 - - [23/Jun/2021 04:11:36] "[35m[1mGET /id/serial-4277 HTTP/1.1[0m" 500 -
INFO:werkzeug:127.0.0.1 - - [23/Jun/2021 04:11:36] "[33mGET /favicon.ico HTTP/1.1[0m" 404 -
INFO:werkzeug: * Running on http://127.0.0.1:5000/ (Press CTRL+C to quit)
ERROR:app:Exception on /id/serial-4277 [GET]
Traceback (most recent call last):
  File "C:\python\lib\site-packages\flask\app.py", line 2447, in wsgi_app
    response = self.full_dispatch_request()
  File "C:\python\lib\site-packages\flask\app.py", line 1952, in full_dispatch_request
    rv = self.handle_user_exception(e)
  File "C:\python\lib\site-packages\flask\app.py", line 1821, in handle_user_exception
    reraise(exc_type, exc_value, tb)
  File "C:\python\lib\site-packages\flask\_compat.py", line 39, in reraise
    raise value
  File "C:\python\lib\site-packages\flask\app.py", line 1950, in full_dispatch_request
    rv = self.dispatch_request()
  File "C:\python\lib\site-packages\flask\app.py", line 1936, in dispatch_request
    return self.view_functions[rule.endpoint](**req.view_args)
  File "C:\Users\Artem\OneDrive\all_python\freelance-animebot\web\app.py", line 17, in main
    anime.views += 1
AttributeError: 'NoneType' object has no attribute 'views'
INFO:werkzeug:127.0.0.1 - - [23/Jun/2021 04:13:05] "[35m[1mGET /id/serial-4277 HTTP/1.1[0m" 500 -
ERROR:app:Exception on /id/serial-4277 [GET]
Traceback (most recent call last):
  File "C:\python\lib\site-packages\flask\app.py", line 2447, in wsgi_app
    response = self.full_dispatch_request()
  File "C:\python\lib\site-packages\flask\app.py", line 1952, in full_dispatch_request
    rv = self.handle_user_exception(e)
  File "C:\python\lib\site-packages\flask\app.py", line 1821, in handle_user_exception
    reraise(exc_type, exc_value, tb)
  File "C:\python\lib\site-packages\flask\_compat.py", line 39, in reraise
    raise value
  File "C:\python\lib\site-packages\flask\app.py", line 1950, in full_dispatch_request
    rv = self.dispatch_request()
  File "C:\python\lib\site-packages\flask\app.py", line 1936, in dispatch_request
    return self.view_functions[rule.endpoint](**req.view_args)
  File "C:\Users\Artem\OneDrive\all_python\freelance-animebot\web\app.py", line 17, in main
    anime.views += 1
AttributeError: 'NoneType' object has no attribute 'views'
INFO:werkzeug:127.0.0.1 - - [23/Jun/2021 04:13:07] "[35m[1mGET /id/serial-4277 HTTP/1.1[0m" 500 -
INFO:werkzeug:127.0.0.1 - - [23/Jun/2021 04:13:07] "[33mGET /favicon.ico HTTP/1.1[0m" 404 -
INFO:werkzeug: * Running on http://127.0.0.1:5000/ (Press CTRL+C to quit)
ERROR:app:Exception on /id/serial-4277 [GET]
Traceback (most recent call last):
  File "C:\python\lib\site-packages\flask\app.py", line 2447, in wsgi_app
    response = self.full_dispatch_request()
  File "C:\python\lib\site-packages\flask\app.py", line 1952, in full_dispatch_request
    rv = self.handle_user_exception(e)
  File "C:\python\lib\site-packages\flask\app.py", line 1821, in handle_user_exception
    reraise(exc_type, exc_value, tb)
  File "C:\python\lib\site-packages\flask\_compat.py", line 39, in reraise
    raise value
  File "C:\python\lib\site-packages\flask\app.py", line 1950, in full_dispatch_request
    rv = self.dispatch_request()
  File "C:\python\lib\site-packages\flask\app.py", line 1936, in dispatch_request
    return self.view_functions[rule.endpoint](**req.view_args)
  File "C:\Users\Artem\OneDrive\all_python\freelance-animebot\web\app.py", line 22, in main
    page_link = f'http://animepoints.cc/{id}'
AttributeError: 'Anime' object has no attribute 'poster_link'
INFO:werkzeug:127.0.0.1 - - [23/Jun/2021 04:19:01] "[35m[1mGET /id/serial-4277 HTTP/1.1[0m" 500 -
ERROR:app:Exception on /id/serial-4277 [GET]
Traceback (most recent call last):
  File "C:\python\lib\site-packages\flask\app.py", line 2447, in wsgi_app
    response = self.full_dispatch_request()
  File "C:\python\lib\site-packages\flask\app.py", line 1952, in full_dispatch_request
    rv = self.handle_user_exception(e)
  File "C:\python\lib\site-packages\flask\app.py", line 1821, in handle_user_exception
    reraise(exc_type, exc_value, tb)
  File "C:\python\lib\site-packages\flask\_compat.py", line 39, in reraise
    raise value
  File "C:\python\lib\site-packages\flask\app.py", line 1950, in full_dispatch_request
    rv = self.dispatch_request()
  File "C:\python\lib\site-packages\flask\app.py", line 1936, in dispatch_request
    return self.view_functions[rule.endpoint](**req.view_args)
  File "C:\Users\Artem\OneDrive\all_python\freelance-animebot\web\app.py", line 22, in main
    page_link = f'http://animepoints.cc/{id}'
AttributeError: 'Anime' object has no attribute 'poster_link'
INFO:werkzeug:127.0.0.1 - - [23/Jun/2021 04:19:03] "[35m[1mGET /id/serial-4277 HTTP/1.1[0m" 500 -
INFO:werkzeug:127.0.0.1 - - [23/Jun/2021 04:19:03] "[33mGET /favicon.ico HTTP/1.1[0m" 404 -
ERROR:app:Exception on /id/serial-4277 [GET]
Traceback (most recent call last):
  File "C:\python\lib\site-packages\flask\app.py", line 2447, in wsgi_app
    response = self.full_dispatch_request()
  File "C:\python\lib\site-packages\flask\app.py", line 1952, in full_dispatch_request
    rv = self.handle_user_exception(e)
  File "C:\python\lib\site-packages\flask\app.py", line 1821, in handle_user_exception
    reraise(exc_type, exc_value, tb)
  File "C:\python\lib\site-packages\flask\_compat.py", line 39, in reraise
    raise value
  File "C:\python\lib\site-packages\flask\app.py", line 1950, in full_dispatch_request
    rv = self.dispatch_request()
  File "C:\python\lib\site-packages\flask\app.py", line 1936, in dispatch_request
    return self.view_functions[rule.endpoint](**req.view_args)
  File "C:\Users\Artem\OneDrive\all_python\freelance-animebot\web\app.py", line 22, in main
    page_link = f'http://animepoints.cc/{id}'
AttributeError: 'Anime' object has no attribute 'poster_link'
INFO:werkzeug:127.0.0.1 - - [23/Jun/2021 04:19:10] "[35m[1mGET /id/serial-4277 HTTP/1.1[0m" 500 -
INFO:werkzeug: * Running on http://127.0.0.1:5000/ (Press CTRL+C to quit)
ERROR:app:Exception on /id/serial-4277 [GET]
Traceback (most recent call last):
  File "C:\python\lib\site-packages\flask\app.py", line 2447, in wsgi_app
    response = self.full_dispatch_request()
  File "C:\python\lib\site-packages\flask\app.py", line 1952, in full_dispatch_request
    rv = self.handle_user_exception(e)
  File "C:\python\lib\site-packages\flask\app.py", line 1821, in handle_user_exception
    reraise(exc_type, exc_value, tb)
  File "C:\python\lib\site-packages\flask\_compat.py", line 39, in reraise
    raise value
  File "C:\python\lib\site-packages\flask\app.py", line 1950, in full_dispatch_request
    rv = self.dispatch_request()
  File "C:\python\lib\site-packages\flask\app.py", line 1936, in dispatch_request
    return self.view_functions[rule.endpoint](**req.view_args)
  File "C:\Users\Artem\OneDrive\all_python\freelance-animebot\web\app.py", line 22, in main
    img_link = anime.poster_link
AttributeError: 'Anime' object has no attribute 'poster_link'
INFO:werkzeug:127.0.0.1 - - [23/Jun/2021 04:20:45] "[35m[1mGET /id/serial-4277 HTTP/1.1[0m" 500 -
INFO:werkzeug:127.0.0.1 - - [23/Jun/2021 04:20:46] "[33mGET /favicon.ico HTTP/1.1[0m" 404 -
INFO:werkzeug: * Running on http://127.0.0.1:5000/ (Press CTRL+C to quit)
INFO:werkzeug:127.0.0.1 - - [23/Jun/2021 04:23:29] "[37mGET /id/serial-4277 HTTP/1.1[0m" 200 -
INFO:werkzeug:127.0.0.1 - - [23/Jun/2021 04:23:29] "[37mGET /static/css/main.css HTTP/1.1[0m" 200 -
INFO:werkzeug:127.0.0.1 - - [23/Jun/2021 04:23:30] "[33mGET /assets/images/favicon.png HTTP/1.1[0m" 404 -
INFO:werkzeug:127.0.0.1 - - [23/Jun/2021 04:23:45] "[37mGET /id/serial-4277 HTTP/1.1[0m" 200 -
INFO:werkzeug:127.0.0.1 - - [23/Jun/2021 04:23:46] "[37mGET /id/serial-4277 HTTP/1.1[0m" 200 -
INFO:werkzeug:127.0.0.1 - - [23/Jun/2021 04:23:46] "[37mGET /id/serial-4277 HTTP/1.1[0m" 200 -
INFO:werkzeug:127.0.0.1 - - [23/Jun/2021 04:23:46] "[37mGET /id/serial-4277 HTTP/1.1[0m" 200 -
INFO:werkzeug:127.0.0.1 - - [23/Jun/2021 04:23:47] "[37mGET /id/serial-4277 HTTP/1.1[0m" 200 -
INFO:werkzeug:127.0.0.1 - - [23/Jun/2021 04:23:47] "[37mGET /id/serial-4277 HTTP/1.1[0m" 200 -
INFO:werkzeug:127.0.0.1 - - [23/Jun/2021 04:23:47] "[37mGET /id/serial-4277 HTTP/1.1[0m" 200 -
INFO:werkzeug:127.0.0.1 - - [23/Jun/2021 04:23:47] "[37mGET /id/serial-4277 HTTP/1.1[0m" 200 -
INFO:werkzeug:127.0.0.1 - - [23/Jun/2021 04:23:47] "[37mGET /id/serial-4277 HTTP/1.1[0m" 200 -
INFO:werkzeug:127.0.0.1 - - [23/Jun/2021 04:23:48] "[37mGET /id/serial-4277 HTTP/1.1[0m" 200 -
INFO:werkzeug:127.0.0.1 - - [23/Jun/2021 04:23:48] "[37mGET /static/favicon.ico HTTP/1.1[0m" 200 -
INFO:werkzeug:127.0.0.1 - - [23/Jun/2021 04:23:52] "[37mGET /id/serial-4277 HTTP/1.1[0m" 200 -
INFO:werkzeug:127.0.0.1 - - [23/Jun/2021 04:23:52] "[37mGET /id/serial-4277 HTTP/1.1[0m" 200 -
INFO:werkzeug:127.0.0.1 - - [23/Jun/2021 04:23:53] "[37mGET /id/serial-4277 HTTP/1.1[0m" 200 -
INFO:werkzeug:127.0.0.1 - - [23/Jun/2021 04:23:53] "[37mGET /id/serial-4277 HTTP/1.1[0m" 200 -
INFO:werkzeug:127.0.0.1 - - [23/Jun/2021 04:23:53] "[37mGET /id/serial-4277 HTTP/1.1[0m" 200 -
INFO:werkzeug:127.0.0.1 - - [23/Jun/2021 04:23:53] "[37mGET /id/serial-4277 HTTP/1.1[0m" 200 -
INFO:werkzeug:127.0.0.1 - - [23/Jun/2021 04:23:54] "[37mGET /id/serial-4277 HTTP/1.1[0m" 200 -
INFO:werkzeug:127.0.0.1 - - [23/Jun/2021 04:23:54] "[37mGET /id/serial-4277 HTTP/1.1[0m" 200 -
INFO:werkzeug:127.0.0.1 - - [23/Jun/2021 04:23:54] "[37mGET /id/serial-4277 HTTP/1.1[0m" 200 -
INFO:werkzeug:127.0.0.1 - - [23/Jun/2021 04:23:54] "[37mGET /id/serial-4277 HTTP/1.1[0m" 200 -
INFO:werkzeug:127.0.0.1 - - [23/Jun/2021 04:23:54] "[37mGET /id/serial-4277 HTTP/1.1[0m" 200 -
INFO:werkzeug:127.0.0.1 - - [23/Jun/2021 04:23:55] "[37mGET /id/serial-4277 HTTP/1.1[0m" 200 -
INFO:werkzeug:127.0.0.1 - - [23/Jun/2021 04:23:55] "[37mGET /id/serial-4277 HTTP/1.1[0m" 200 -
INFO:werkzeug:127.0.0.1 - - [23/Jun/2021 04:23:55] "[37mGET /id/serial-4277 HTTP/1.1[0m" 200 -
INFO:werkzeug:127.0.0.1 - - [23/Jun/2021 04:23:55] "[37mGET /id/serial-4277 HTTP/1.1[0m" 200 -
INFO:werkzeug:127.0.0.1 - - [23/Jun/2021 04:23:55] "[37mGET /id/serial-4277 HTTP/1.1[0m" 200 -
INFO:werkzeug:127.0.0.1 - - [23/Jun/2021 04:23:56] "[37mGET /id/serial-4277 HTTP/1.1[0m" 200 -
INFO:werkzeug:127.0.0.1 - - [23/Jun/2021 04:23:56] "[37mGET /id/serial-4277 HTTP/1.1[0m" 200 -
INFO:werkzeug:127.0.0.1 - - [23/Jun/2021 04:23:56] "[37mGET /id/serial-4277 HTTP/1.1[0m" 200 -
INFO:werkzeug:127.0.0.1 - - [23/Jun/2021 04:23:56] "[37mGET /id/serial-4277 HTTP/1.1[0m" 200 -
INFO:werkzeug:127.0.0.1 - - [23/Jun/2021 04:23:57] "[37mGET /id/serial-4277 HTTP/1.1[0m" 200 -
INFO:werkzeug:127.0.0.1 - - [23/Jun/2021 04:23:57] "[37mGET /id/serial-4277 HTTP/1.1[0m" 200 -
INFO:werkzeug:127.0.0.1 - - [23/Jun/2021 04:23:57] "[37mGET /id/serial-4277 HTTP/1.1[0m" 200 -
INFO:werkzeug:127.0.0.1 - - [23/Jun/2021 04:23:57] "[37mGET /id/serial-4277 HTTP/1.1[0m" 200 -
INFO:werkzeug:127.0.0.1 - - [23/Jun/2021 04:23:58] "[37mGET /id/serial-4277 HTTP/1.1[0m" 200 -
INFO:werkzeug:127.0.0.1 - - [23/Jun/2021 04:23:58] "[37mGET /id/serial-4277 HTTP/1.1[0m" 200 -
INFO:werkzeug:127.0.0.1 - - [23/Jun/2021 04:23:58] "[37mGET /id/serial-4277 HTTP/1.1[0m" 200 -
INFO:werkzeug:127.0.0.1 - - [23/Jun/2021 04:23:59] "[37mGET /static/favicon.ico HTTP/1.1[0m" 200 -
INFO:werkzeug: * Running on http://127.0.0.1:5000/ (Press CTRL+C to quit)
INFO:werkzeug:127.0.0.1 - - [23/Jun/2021 22:59:45] "[37mGET /id/serial-23259 HTTP/1.1[0m" 200 -
INFO:werkzeug:127.0.0.1 - - [23/Jun/2021 22:59:45] "[36mGET /static/css/main.css HTTP/1.1[0m" 304 -
INFO:werkzeug:127.0.0.1 - - [23/Jun/2021 22:59:46] "[33mGET /assets/images/favicon.png HTTP/1.1[0m" 404 -
INFO:werkzeug:127.0.0.1 - - [23/Jun/2021 22:59:53] "[33mGET /assets/images/favicon.png HTTP/1.1[0m" 404 -
INFO:werkzeug:127.0.0.1 - - [24/Jun/2021 01:32:05] "[37mGET /id/movie-74420 HTTP/1.1[0m" 200 -
INFO:werkzeug:127.0.0.1 - - [24/Jun/2021 01:32:05] "[33mGET /assets/images/favicon.png HTTP/1.1[0m" 404 -
INFO:werkzeug:127.0.0.1 - - [24/Jun/2021 01:32:19] "[33mGET /assets/images/favicon.png HTTP/1.1[0m" 404 -
INFO:werkzeug:127.0.0.1 - - [24/Jun/2021 01:32:28] "[33mGET /assets/images/favicon.png HTTP/1.1[0m" 404 -
INFO:werkzeug:127.0.0.1 - - [24/Jun/2021 01:33:15] "[33mGET /assets/images/favicon.png HTTP/1.1[0m" 404 -
INFO:werkzeug: * Running on http://127.0.0.1:5000/ (Press CTRL+C to quit)
ERROR:app:Exception on /id/serial-34904 [GET]
Traceback (most recent call last):
  File "C:\python\lib\site-packages\flask\app.py", line 2447, in wsgi_app
    response = self.full_dispatch_request()
  File "C:\python\lib\site-packages\flask\app.py", line 1952, in full_dispatch_request
    rv = self.handle_user_exception(e)
  File "C:\python\lib\site-packages\flask\app.py", line 1821, in handle_user_exception
    reraise(exc_type, exc_value, tb)
  File "C:\python\lib\site-packages\flask\_compat.py", line 39, in reraise
    raise value
  File "C:\python\lib\site-packages\flask\app.py", line 1950, in full_dispatch_request
    rv = self.dispatch_request()
  File "C:\python\lib\site-packages\flask\app.py", line 1936, in dispatch_request
    return self.view_functions[rule.endpoint](**req.view_args)
  File "C:\Users\Artem\OneDrive\all_python\freelance-animebot\web\app.py", line 17, in main
    anime.views += 1
AttributeError: 'NoneType' object has no attribute 'views'
INFO:werkzeug:127.0.0.1 - - [24/Jun/2021 04:22:04] "[35m[1mGET /id/serial-34904 HTTP/1.1[0m" 500 -
INFO:werkzeug:127.0.0.1 - - [24/Jun/2021 04:22:05] "[33mGET /favicon.ico HTTP/1.1[0m" 404 -
ERROR:app:Exception on /id/serial-34904 [GET]
Traceback (most recent call last):
  File "C:\python\lib\site-packages\flask\app.py", line 2447, in wsgi_app
    response = self.full_dispatch_request()
  File "C:\python\lib\site-packages\flask\app.py", line 1952, in full_dispatch_request
    rv = self.handle_user_exception(e)
  File "C:\python\lib\site-packages\flask\app.py", line 1821, in handle_user_exception
    reraise(exc_type, exc_value, tb)
  File "C:\python\lib\site-packages\flask\_compat.py", line 39, in reraise
    raise value
  File "C:\python\lib\site-packages\flask\app.py", line 1950, in full_dispatch_request
    rv = self.dispatch_request()
  File "C:\python\lib\site-packages\flask\app.py", line 1936, in dispatch_request
    return self.view_functions[rule.endpoint](**req.view_args)
  File "C:\Users\Artem\OneDrive\all_python\freelance-animebot\web\app.py", line 17, in main
    anime.views += 1
AttributeError: 'NoneType' object has no attribute 'views'
INFO:werkzeug:127.0.0.1 - - [24/Jun/2021 04:22:06] "[35m[1mGET /id/serial-34904 HTTP/1.1[0m" 500 -
ERROR:app:Exception on /id/serial-34904 [GET]
Traceback (most recent call last):
  File "C:\python\lib\site-packages\flask\app.py", line 2447, in wsgi_app
    response = self.full_dispatch_request()
  File "C:\python\lib\site-packages\flask\app.py", line 1952, in full_dispatch_request
    rv = self.handle_user_exception(e)
  File "C:\python\lib\site-packages\flask\app.py", line 1821, in handle_user_exception
    reraise(exc_type, exc_value, tb)
  File "C:\python\lib\site-packages\flask\_compat.py", line 39, in reraise
    raise value
  File "C:\python\lib\site-packages\flask\app.py", line 1950, in full_dispatch_request
    rv = self.dispatch_request()
  File "C:\python\lib\site-packages\flask\app.py", line 1936, in dispatch_request
    return self.view_functions[rule.endpoint](**req.view_args)
  File "C:\Users\Artem\OneDrive\all_python\freelance-animebot\web\app.py", line 17, in main
    anime.views += 1
AttributeError: 'NoneType' object has no attribute 'views'
INFO:werkzeug:127.0.0.1 - - [24/Jun/2021 04:22:10] "[35m[1mGET /id/serial-34904 HTTP/1.1[0m" 500 -
ERROR:app:Exception on /id/serial-34904 [GET]
Traceback (most recent call last):
  File "C:\python\lib\site-packages\flask\app.py", line 2447, in wsgi_app
    response = self.full_dispatch_request()
  File "C:\python\lib\site-packages\flask\app.py", line 1952, in full_dispatch_request
    rv = self.handle_user_exception(e)
  File "C:\python\lib\site-packages\flask\app.py", line 1821, in handle_user_exception
    reraise(exc_type, exc_value, tb)
  File "C:\python\lib\site-packages\flask\_compat.py", line 39, in reraise
    raise value
  File "C:\python\lib\site-packages\flask\app.py", line 1950, in full_dispatch_request
    rv = self.dispatch_request()
  File "C:\python\lib\site-packages\flask\app.py", line 1936, in dispatch_request
    return self.view_functions[rule.endpoint](**req.view_args)
  File "C:\Users\Artem\OneDrive\all_python\freelance-animebot\web\app.py", line 17, in main
    anime.views += 1
AttributeError: 'NoneType' object has no attribute 'views'
INFO:werkzeug:127.0.0.1 - - [24/Jun/2021 04:22:11] "[35m[1mGET /id/serial-34904 HTTP/1.1[0m" 500 -
ERROR:app:Exception on /id/serial-34904 [GET]
Traceback (most recent call last):
  File "C:\python\lib\site-packages\flask\app.py", line 2447, in wsgi_app
    response = self.full_dispatch_request()
  File "C:\python\lib\site-packages\flask\app.py", line 1952, in full_dispatch_request
    rv = self.handle_user_exception(e)
  File "C:\python\lib\site-packages\flask\app.py", line 1821, in handle_user_exception
    reraise(exc_type, exc_value, tb)
  File "C:\python\lib\site-packages\flask\_compat.py", line 39, in reraise
    raise value
  File "C:\python\lib\site-packages\flask\app.py", line 1950, in full_dispatch_request
    rv = self.dispatch_request()
  File "C:\python\lib\site-packages\flask\app.py", line 1936, in dispatch_request
    return self.view_functions[rule.endpoint](**req.view_args)
  File "C:\Users\Artem\OneDrive\all_python\freelance-animebot\web\app.py", line 17, in main
    anime.views += 1
AttributeError: 'NoneType' object has no attribute 'views'
INFO:werkzeug:127.0.0.1 - - [24/Jun/2021 04:22:11] "[35m[1mGET /id/serial-34904 HTTP/1.1[0m" 500 -
INFO:werkzeug:127.0.0.1 - - [24/Jun/2021 04:22:43] "[37mGET /id/serial-34904 HTTP/1.1[0m" 200 -
INFO:werkzeug:127.0.0.1 - - [24/Jun/2021 04:22:44] "[33mGET /assets/images/favicon.png HTTP/1.1[0m" 404 -
INFO:werkzeug:127.0.0.1 - - [24/Jun/2021 04:22:53] "[33mGET /assets/images/favicon.png HTTP/1.1[0m" 404 -
INFO:werkzeug:127.0.0.1 - - [24/Jun/2021 05:14:45] "[37mGET /id/serial-33871 HTTP/1.1[0m" 200 -
INFO:werkzeug: * Running on http://127.0.0.1:5000/ (Press CTRL+C to quit)
ERROR:app:Exception on /id/movie-74228 [GET]
Traceback (most recent call last):
  File "C:\python\lib\site-packages\flask\app.py", line 2447, in wsgi_app
    response = self.full_dispatch_request()
  File "C:\python\lib\site-packages\flask\app.py", line 1952, in full_dispatch_request
    rv = self.handle_user_exception(e)
  File "C:\python\lib\site-packages\flask\app.py", line 1821, in handle_user_exception
    reraise(exc_type, exc_value, tb)
  File "C:\python\lib\site-packages\flask\_compat.py", line 39, in reraise
    raise value
  File "C:\python\lib\site-packages\flask\app.py", line 1950, in full_dispatch_request
    rv = self.dispatch_request()
  File "C:\python\lib\site-packages\flask\app.py", line 1936, in dispatch_request
    return self.view_functions[rule.endpoint](**req.view_args)
  File "C:\Users\Artem\OneDrive\all_python\freelance-animebot\web\app.py", line 17, in main
    anime.views += 1
AttributeError: 'NoneType' object has no attribute 'views'
INFO:werkzeug:127.0.0.1 - - [24/Jun/2021 06:35:50] "[35m[1mGET /id/movie-74228 HTTP/1.1[0m" 500 -
INFO:werkzeug: * Running on http://127.0.0.1:5000/ (Press CTRL+C to quit)
ERROR:app:Exception on /id/movie-74228 [GET]
Traceback (most recent call last):
  File "C:\python\lib\site-packages\flask\app.py", line 2447, in wsgi_app
    response = self.full_dispatch_request()
  File "C:\python\lib\site-packages\flask\app.py", line 1952, in full_dispatch_request
    rv = self.handle_user_exception(e)
  File "C:\python\lib\site-packages\flask\app.py", line 1821, in handle_user_exception
    reraise(exc_type, exc_value, tb)
  File "C:\python\lib\site-packages\flask\_compat.py", line 39, in reraise
    raise value
  File "C:\python\lib\site-packages\flask\app.py", line 1950, in full_dispatch_request
    rv = self.dispatch_request()
  File "C:\python\lib\site-packages\flask\app.py", line 1936, in dispatch_request
    return self.view_functions[rule.endpoint](**req.view_args)
  File "C:\Users\Artem\OneDrive\all_python\freelance-animebot\web\app.py", line 17, in main
    anime.views += 1
AttributeError: 'NoneType' object has no attribute 'views'
INFO:werkzeug:127.0.0.1 - - [24/Jun/2021 06:36:28] "[35m[1mGET /id/movie-74228 HTTP/1.1[0m" 500 -
INFO:werkzeug:127.0.0.1 - - [24/Jun/2021 06:36:28] "[33mGET /favicon.ico HTTP/1.1[0m" 404 -
INFO:werkzeug:127.0.0.1 - - [24/Jun/2021 06:36:45] "[37mGET /id/serial-35375 HTTP/1.1[0m" 200 -
INFO:werkzeug:127.0.0.1 - - [24/Jun/2021 06:36:46] "[33mGET /assets/images/favicon.png HTTP/1.1[0m" 404 -
ERROR:app:Exception on /id/movie-74228 [GET]
Traceback (most recent call last):
  File "C:\python\lib\site-packages\flask\app.py", line 2447, in wsgi_app
    response = self.full_dispatch_request()
  File "C:\python\lib\site-packages\flask\app.py", line 1952, in full_dispatch_request
    rv = self.handle_user_exception(e)
  File "C:\python\lib\site-packages\flask\app.py", line 1821, in handle_user_exception
    reraise(exc_type, exc_value, tb)
  File "C:\python\lib\site-packages\flask\_compat.py", line 39, in reraise
    raise value
  File "C:\python\lib\site-packages\flask\app.py", line 1950, in full_dispatch_request
    rv = self.dispatch_request()
  File "C:\python\lib\site-packages\flask\app.py", line 1936, in dispatch_request
    return self.view_functions[rule.endpoint](**req.view_args)
  File "C:\Users\Artem\OneDrive\all_python\freelance-animebot\web\app.py", line 17, in main
    anime.views += 1
AttributeError: 'NoneType' object has no attribute 'views'
INFO:werkzeug:127.0.0.1 - - [24/Jun/2021 06:36:51] "[35m[1mGET /id/movie-74228 HTTP/1.1[0m" 500 -
INFO:werkzeug:127.0.0.1 - - [24/Jun/2021 06:37:10] "[37mGET /id/serial-23259 HTTP/1.1[0m" 200 -
INFO:werkzeug: * Running on http://127.0.0.1:5000/ (Press CTRL+C to quit)
INFO:werkzeug:127.0.0.1 - - [25/Jun/2021 05:25:08] "[37mGET /id/serial-35419 HTTP/1.1[0m" 200 -
INFO:werkzeug:127.0.0.1 - - [25/Jun/2021 05:25:09] "[37mGET /static/css/main.css HTTP/1.1[0m" 200 -
INFO:werkzeug:127.0.0.1 - - [25/Jun/2021 05:25:09] "[33mGET /assets/images/favicon.png HTTP/1.1[0m" 404 -
INFO:werkzeug:127.0.0.1 - - [25/Jun/2021 05:25:14] "[33mGET /assets/images/favicon.png HTTP/1.1[0m" 404 -
